<?xml version="1.0"?>
<robot name="adeept_awr">
		<link name = "base" />
	<joint name = "base_to_chassis" type="fixed">
		<parent link = "base"/>
		<child link = "chassis"/>
		<origin xyz = "0.0 0.0 0.055"/>
	</joint>

	<link name="front_right_wheel">
		<visual>
			<origin xyz="0.0 -0.0125 0.0" rpy="1.5708 0 0"/>
			<geometry>
				<cylinder radius="0.0325" length="0.025"/>
			</geometry>
		</visual>
		<collision>
			<origin xyz="0.0 -0.0125 0.0" rpy="1.5708 0 0"/>
			<geometry>
				<cylinder radius="0.0325" length="0.025"/>
			</geometry>
		</collision>
		<inertial>
			<origin xyz="0.0 -0.0125 0.0"/>
			<mass value="0.03"/>
			<inertia ixx="0.00001044" ixy="0.0" ixz="0" iyy="0.00001767" iyz="0.0" izz="0.00001044"/>
		</inertial>
	</link>
	<joint name = "front_right_axle" type="continuous">
		<parent link = "chassis"/>
		<child link = "front_right_wheel"/>
		<origin xyz = "0.03 -0.06 -0.02"/>
		<axis xyz = "0 1 0" />
	</joint>
	<link name="rear_left_wheel">
		<visual>
			<origin xyz="0.0 0.0125 0.0" rpy="1.5708 0 0"/>
			<geometry>
				<cylinder radius="0.0325" length="0.025"/>
			</geometry>
		</visual>
		<collision>
			<origin xyz="0.0 0.0125 0.0" rpy="1.5708 0 0"/>
			<geometry>
				<cylinder radius="0.0325" length="0.025"/>
			</geometry>
		</collision>
		<inertial>
			<origin xyz="0.0 0.0125 0.0"/>
			<mass value="0.03"/>
			<inertia ixx="0.00001044" ixy="0.0" ixz="0" iyy="0.00001767" iyz="0.0" izz="0.00001044"/>
		</inertial>
	</link>
	<link name="rear_right_wheel">
		<visual>
			<origin xyz="0.0 -0.0125 0.0" rpy="1.5708 0 0"/>
			<geometry>
				<cylinder radius="0.0325" length="0.025"/>
			</geometry>
		</visual>
		<collision>
			<origin xyz="0.0 -0.0125 0.0" rpy="1.5708 0 0"/>
			<geometry>
				<cylinder radius="0.0325" length="0.025"/>
			</geometry>
		</collision>
		<inertial>
			<origin xyz="0.0 -0.0125 0.0"/>
			<mass value="0.03"/>
			<inertia ixx="0.00001044" ixy="0.0" ixz="0" iyy="0.00001767" iyz="0.0" izz="0.00001044"/>
		</inertial>
	</link>
	<joint name = "rear_right_axle" type="continuous">
		<parent link = "chassis"/>
		<child link = "rear_right_wheel"/>
		<origin xyz = "-0.05 -0.06 -0.02"/>
		<axis xyz = "0 1 0" />
	</joint>
	<joint name = "rear_left_axle" type="continuous">
		<parent link = "chassis"/>
		<child link = "rear_left_wheel"/>
		<origin xyz = "-0.05 0.06 -0.02"/>
		<axis xyz = "0 1 0" />
	</joint>
	<joint name = "front_left_axle" type="continuous">
		<parent link = "chassis"/>
		<child link = "front_left_wheel"/>
		<origin xyz = "0.03 0.06 -0.02"/>
		<axis xyz = "0 1 0" />
	</joint>
	<link name="front_left_wheel">
		<visual>
			<origin xyz="0.0 0.0125 0.0" rpy="1.5708 0 0"/>
			<geometry>
				<cylinder radius="0.0325" length="0.025"/>
			</geometry>
		</visual>
		<collision>
			<origin xyz="0.0 0.0125 0.0" rpy="1.5708 0 0"/>
			<geometry>
				<cylinder radius="0.0325" length="0.025"/>
			</geometry>
		</collision>
		<inertial>
			<origin xyz="0.0 0.0125 0.0"/>
			<mass value="0.03"/>
			<inertia ixx="0.00001044" ixy="0.0" ixz="0" iyy="0.00001767" iyz="0.0" izz="0.00001044"/>
		</inertial>
	</link>
		<link name="chassis">
		<visual>
			<geometry>
				<box size = "0.13 0.12 0.08"/>
			</geometry>
		</visual>
		<collision>
			<geometry>
				<box size = "0.13 0.12 0.08"/>
			</geometry>
		</collision>
	</link>
</robot>