<?xml version="1.0"?>
<robot name="adeept_awr">
  <link name="chassis">
    <origin xyz = "0.0 0.0 0.055"/>
    <visual>
      <geometry>
        <box size = "0.13 0.12 0.08"/>
      </geometry>
    </visual>
    <collision>
      <geometry>
        <box size = "0.13 0.12 0.08"/>
      </geometry>
    </collision>
    <inertial>
      <origin xyz="0.0 0.0125 0.0"/>
      <mass value="0.500"/>
      <inertia ixx="0.00009565" ixy="0.0" ixz="0" iyy="0.0003999" iyz="0.0" izz="0.0004892"/>
    </inertial>
  </link>
  <link name="battery">
    <origin xyz = "0.0 0.0 0.0"/>
    <visual>
      <geometry>
        <box size = "0.145 0.065 0.015"/>
      </geometry>
    </visual>
    <collision>
      <geometry>
        <box size = "0.145 0.065 0.015"/>
      </geometry>
    </collision>
    <inertial>
      <origin xyz = "0.0 0.0 0.0"/>
      <mass value="0.230"/>
      <inertia ixx="0.00009435" ixy="0.0" ixz="0" iyy="0.00001117" iyz="0.0" izz="0.0000148"/>
    </inertial>
  </link>
  <link name="front_left_wheel">
    <visual>
      <origin xyz="0.0 0.0125 0.0" rpy="1.5708 0 0"/>
      <geometry>
        <cylinder radius="0.0325" length="0.025"/>
      </geometry>
    </visual>
    <collision>
      <origin xyz="0.0 0.0125 0.0" rpy="1.5708 0 0"/>
      <geometry>
        <cylinder radius="0.0325" length="0.025"/>
      </geometry>
    </collision>
    <inertial>
      <origin xyz="0.0 0.0125 0.0"/>
      <mass value="0.03"/>
      <inertia ixx="0.00001044" ixy="0.0" ixz="0" iyy="0.00001767" iyz="0.0" izz="0.00001044"/>
    </inertial>
  </link>
  <link name="front_right_wheel">
    <visual>
      <origin xyz="0.0 -0.0125 0.0" rpy="1.5708 0 0"/>
      <geometry>
        <cylinder radius="0.0325" length="0.025"/>
      </geometry>
    </visual>
    <collision>
      <origin xyz="0.0 -0.0125 0.0" rpy="1.5708 0 0"/>
      <geometry>
        <cylinder radius="0.0325" length="0.025"/>
      </geometry>
    </collision>
    <inertial>
      <origin xyz="0.0 -0.0125 0.0"/>
      <mass value="0.03"/>
      <inertia ixx="0.00001044" ixy="0.0" ixz="0" iyy="0.00001767" iyz="0.0" izz="0.00001044"/>
    </inertial>
  </link>
  <link name="rear_left_wheel">
    <visual>
      <origin xyz="0.0 0.0125 0.0" rpy="1.5708 0 0"/>
      <geometry>
        <cylinder radius="0.0325" length="0.025"/>
      </geometry>
    </visual>
    <collision>
      <origin xyz="0.0 0.0125 0.0" rpy="1.5708 0 0"/>
      <geometry>
        <cylinder radius="0.0325" length="0.025"/>
      </geometry>
    </collision>
    <inertial>
      <origin xyz="0.0 0.0125 0.0"/>
      <mass value="0.03"/>
      <inertia ixx="0.00001044" ixy="0.0" ixz="0" iyy="0.00001767" iyz="0.0" izz="0.00001044"/>
    </inertial>
  </link>
  <link name="rear_right_wheel">
    <visual>
      <origin xyz="0.0 -0.0125 0.0" rpy="1.5708 0 0"/>
      <geometry>
        <cylinder radius="0.0325" length="0.025"/>
      </geometry>
    </visual>
    <collision>
      <origin xyz="0.0 -0.0125 0.0" rpy="1.5708 0 0"/>
      <geometry>
        <cylinder radius="0.0325" length="0.025"/>
      </geometry>
    </collision>
    <inertial>
      <origin xyz="0.0 -0.0125 0.0"/>
      <mass value="0.03"/>
      <inertia ixx="0.00001044" ixy="0.0" ixz="0" iyy="0.00001767" iyz="0.0" izz="0.00001044"/>
    </inertial>
  </link>
  <joint name = "battery_mount" type="fixed">
    <parent link = "chassis"/>
    <child link = "battery"/>
    <origin xyz = "0.015 0.0 0.0475"/>
  </joint>
  <joint name = "rear_right_axle" type="continuous">
    <parent link = "chassis"/>
    <child link = "rear_right_wheel"/>
    <origin xyz = "-0.05 -0.06 -0.02"/>
    <axis xyz = "0 1 0" />
    <limit effort = "0.0784532" velocity="1.55"/>
    <dynamics friction="0.04"/>
  </joint>
  <joint name = "rear_left_axle" type="continuous">
    <parent link = "chassis"/>
    <child link = "rear_left_wheel"/>
    <origin xyz = "-0.05 0.06 -0.02"/>
    <axis xyz = "0 1 0" />
    <limit effort = "0.0784532" velocity="1.55"/>
    <dynamics friction="0.04"/>
  </joint>
  <joint name = "front_left_axle" type="continuous">
    <parent link = "chassis"/>
    <child link = "front_left_wheel"/>
    <origin xyz = "0.03 0.06 -0.02"/>
    <axis xyz = "0 1 0" />
    <limit effort = "0.0784532" velocity="1.55"/>
    <dynamics friction="0.04"/>
  </joint>
  <joint name = "front_right_axle" type="continuous">
    <parent link = "chassis"/>
    <child link = "front_right_wheel"/>
    <origin xyz = "0.03 -0.06 -0.02"/>
    <axis xyz = "0 1 0" />
    <limit effort = "0.0784532" velocity="1.55"/>
    <dynamics friction="0.04"/>
  </joint>
  <gazebo reference="front_right_wheel">
    <mu1>0.8693</mu1>
    <mu2>0.8693</mu2>
    <material>Gazebo/Black</material>
  </gazebo>
  <gazebo reference="front_left_wheel">
    <mu1>0.8693</mu1>
    <mu2>0.8693</mu2>
    <material>Gazebo/Black</material>
  </gazebo>
  <gazebo reference="rear_right_wheel">
    <mu1>0.8693</mu1>
    <mu2>0.8693</mu2>
    <material>Gazebo/Black</material>
  </gazebo>
  <gazebo reference="rear_left_wheel">
    <mu1>0.8693</mu1>
    <mu2>0.8693</mu2>
    <material>Gazebo/Black</material>
  </gazebo>
  <gazebo>
    <plugin name="skid_steer_drive_controller" filename="libgazebo_ros_skid_steer_drive.so">
      <updateRate>30.0</updateRate>
      <leftFrontJoint>front_left_axle</leftFrontJoint>
      <rightFrontJoint>front_right_axle</rightFrontJoint>
      <leftRearJoint>rear_left_axle</leftRearJoint>
      <rightRearJoint>rear_right_axle</rightRearJoint>
      <wheelSeparation>0.150</wheelSeparation>
      <wheelDiameter>0.065</wheelDiameter>
      <robotBaseFrame>chassis</robotBaseFrame>
      <torque>0.0784532</torque>
      <topicName>cmd_vel</topicName>
      <broadcastTF>true</broadcastTF>
    </plugin>
    <plugin name="joint_state_publisher" filename="libgazebo_ros_joint_state_publisher.so">
      <jointName>front_left_axle,front_right_axle,rear_left_axle,rear_right_axle</jointName>
      <updateRate>40.0</updateRate>
      <alwaysOn>true</alwaysOn>
    </plugin>
  </gazebo>
</robot>